1741803480731	Sync.SyncScheduler	DEBUG	Next sync in 600000 ms. (why=schedule)
1741804077378	Sync.SyncScheduler	DEBUG	Network link status changed to "down". Offline?: false
1741804077379	Sync.SyncScheduler	DEBUG	Clearing sync triggers and the global score.
1741804077383	Sync.SyncScheduler	DEBUG	Next sync in 3600000 ms. (why=schedule)
1741804077385	Sync.SyncScheduler	DEBUG	Network link status changed to "changed". Offline?: false
1741804263631	Sync.Service	DEBUG	User-Agent: Firefox/136.0-2 (Linux x86_64) FxSync/1.138.0.20250305223037.desktop
1741804263631	Sync.Service	INFO	Starting sync at 2025-03-12 20:31:03 in browser session i-2rCsEAozKo
1741804263631	Sync.SyncScheduler	DEBUG	Clearing sync triggers and the global score.
1741804263636	Sync.Status	INFO	Resetting Status.
1741804263636	Sync.Status	DEBUG	Status.service: success.status_ok => success.status_ok
1741804263637	FirefoxAccounts	DEBUG	FxAccountsProfileClient: Requested profile
1741804263637	FirefoxAccounts	DEBUG	getOAuthToken enter
1741804263639	FirefoxAccounts	TRACE	getCachedToken returning cached token
1741804263639	FirefoxAccounts	DEBUG	getOAuthToken returning a cached token
1741804263639	Services.Common.RESTRequest	DEBUG	GET request to https://profile.accounts.firefox.com/v1/profile
1741804263645	Services.Common.RESTRequest	DEBUG	GET https://profile.accounts.firefox.com/v1/profile failed: 2152398878 - NS_ERROR_UNKNOWN_HOST
1741804263645	FirefoxAccounts	ERROR	Background refresh of profile failed: {"name":"FxAccountsProfileClientError","code":null,"errno":998,"error":"NETWORK_ERROR","message":"[Exception... \"NS_ERROR_UNKNOWN_HOST\"  nsresult: \"0x804b001e (NS_ERROR_UNKNOWN_HOST)\"  location: \"JS frame :: resource://services-common/rest.sys.mjs :: onStopRequest :: line 478\"  data: no]"}
1741804263646	Sync.Resource	WARN	GET request to https://sync-1-us-west1-g.sync.services.mozilla.com/1.5/186972506/info/collections failed: [Exception... "The lookup of the hostname failed"  nsresult: "0x804b001e (NS_ERROR_UNKNOWN_HOST)"  location: "<unknown>"  data: no] No traceback available
1741804263646	Sync.Status	DEBUG	Status.sync: success.sync => error.login.reason.network
1741804263646	Sync.Status	DEBUG	Status.service: success.status_ok => error.sync.failed
1741804263646	Sync.ErrorHandler	ERROR	Sync encountered an error: [Exception... "The lookup of the hostname failed"  nsresult: "0x804b001e (NS_ERROR_UNKNOWN_HOST)"  location: "<unknown>"  data: no] No traceback available
1741804263647	Sync.SyncScheduler	DEBUG	Next sync in 600000 ms. (why=reschedule)
1741804263649	Sync.Service	DEBUG	Exception calling anonymous function: [Exception... "The lookup of the hostname failed"  nsresult: "0x804b001e (NS_ERROR_UNKNOWN_HOST)"  location: "<unknown>"  data: no] No traceback available
