1741846061558	Sync.SyncScheduler	DEBUG	Next sync in 600000 ms. (why=schedule)
1741846079423	Sync.SyncScheduler	DEBUG	Network link status changed to "down". Offline?: false
1741846079423	Sync.SyncScheduler	DEBUG	Clearing sync triggers and the global score.
1741846079424	Sync.SyncScheduler	DEBUG	Next sync in 600000 ms. (why=schedule)
1741846079424	Sync.SyncScheduler	DEBUG	Network link status changed to "changed". Offline?: false
1741846344689	Sync.Service	DEBUG	User-Agent: Firefox/136.0.1-1 (Linux x86_64) FxSync/1.138.0.20250312185749.desktop
1741846344689	Sync.Service	INFO	Starting sync at 2025-03-13 08:12:24 in browser session XpIz5dbZuRSr
1741846344689	Sync.SyncScheduler	DEBUG	Clearing sync triggers and the global score.
1741846344691	Sync.Status	INFO	Resetting Status.
1741846344691	Sync.Status	DEBUG	Status.service: success.status_ok => success.status_ok
1741846344691	FirefoxAccounts	DEBUG	FxAccountsProfileClient: Requested profile
1741846344691	FirefoxAccounts	DEBUG	getOAuthToken enter
1741846344692	FirefoxAccounts	TRACE	getCachedToken returning cached token
1741846344692	FirefoxAccounts	DEBUG	getOAuthToken returning a cached token
1741846344692	Services.Common.RESTRequest	DEBUG	GET request to https://profile.accounts.firefox.com/v1/profile
1741846344694	Services.Common.RESTRequest	DEBUG	GET https://profile.accounts.firefox.com/v1/profile failed: 2152398878 - NS_ERROR_UNKNOWN_HOST
1741846344694	FirefoxAccounts	ERROR	Background refresh of profile failed: {"name":"FxAccountsProfileClientError","code":null,"errno":998,"error":"NETWORK_ERROR","message":"[Exception... \"NS_ERROR_UNKNOWN_HOST\"  nsresult: \"0x804b001e (NS_ERROR_UNKNOWN_HOST)\"  location: \"JS frame :: resource://services-common/rest.sys.mjs :: onStopRequest :: line 478\"  data: no]"}
1741846344694	Sync.Resource	WARN	GET request to https://sync-1-us-west1-g.sync.services.mozilla.com/1.5/186972506/info/collections failed: [Exception... "The lookup of the hostname failed"  nsresult: "0x804b001e (NS_ERROR_UNKNOWN_HOST)"  location: "<unknown>"  data: no] No traceback available
1741846344694	Sync.Status	DEBUG	Status.sync: success.sync => error.login.reason.network
1741846344694	Sync.Status	DEBUG	Status.service: success.status_ok => error.sync.failed
1741846344694	Sync.ErrorHandler	ERROR	Sync encountered an error: [Exception... "The lookup of the hostname failed"  nsresult: "0x804b001e (NS_ERROR_UNKNOWN_HOST)"  location: "<unknown>"  data: no] No traceback available
1741846344695	Sync.SyncScheduler	DEBUG	Next sync in 600000 ms. (why=reschedule)
1741846344696	Sync.Service	DEBUG	Exception calling anonymous function: [Exception... "The lookup of the hostname failed"  nsresult: "0x804b001e (NS_ERROR_UNKNOWN_HOST)"  location: "<unknown>"  data: no] No traceback available
